### try...catch
我们应该吧所有可能会抛出错误的代码都放在try语句中，而把那些用户错误处理的代码放在catch中
如果try中的语句发生了错误，就会退出代码执行过程，然后接着执行catch块。
```js
try{
	window.someNonexistentFunction();
}catch(error){
	alert(error.message);
}
```
`finally`其内的代码无论如何都会执行。甚至`return`语句都不会阻止finally执行

### 七种错误类型
- Error 该类型主要是提供给开发人员抛出自定义错误的
- EvalError 使用eval()函数抛出的错误
- RangeError 数值超出相应的范围时触发
- ReferenceError 访问的变量不存在时报的错误，引用错误
- SyntaxError 语法错误
- TypeError 在变量中保存着意外的类型时，或者访问不存在的方法时都会导致这种错误
- URIError 使用encodeURI或者decodeURI时，如果URI格式不正确，就会导致这个错误

### 抛出错误
`throw`操作符，用于随时抛出自定义错误。抛出错误时，必须要给throw操作符指定一个值，这个值是什么类型没有要求
```js
throw 'hello world';
throw new Error('some bad thing happened');
```
要针对函数为什么会执行失败给出更多信息，抛出自定义错误是一种很方便的方式。在编写JavaScript函数时，应该重点关注函数可能造成那些错误，确保函数自由自己抛出的错误

### 错误事件
任何没有通过try...catch处理的错误都会触发window对象的error事件，这个事件是web浏览器最早支持的事件之一
接收三个参数
- 错误消息
- 错误所在URL
- 行号
```js
window.onerror = function(message, url, line){
	alert(message);
	return false; // 阻止浏览器报错的默认行为
}
```
对于大型的应用程序来说自定义的错误通常都是使用`assert()`函数抛出
```js
function assert(condition, message){
	if(!condition){
		throw new Error(message);
	}
}
```